2024-02-12 23:18:44,749 ERROR: Exception on / [GET] [in /home/varadv3/miniconda3/envs/microblog/lib/python3.11/site-packages/flask/app.py : 825]
Traceback (most recent call last):
  File "/home/varadv3/miniconda3/envs/microblog/lib/python3.11/site-packages/flask/app.py", line 1455, in wsgi_app
    response = self.full_dispatch_request()
               ^^^^^^^^^^^^^^^^^^^^^^^^^^^^
  File "/home/varadv3/miniconda3/envs/microblog/lib/python3.11/site-packages/flask/app.py", line 869, in full_dispatch_request
    rv = self.handle_user_exception(e)
         ^^^^^^^^^^^^^^^^^^^^^^^^^^^^^
  File "/home/varadv3/miniconda3/envs/microblog/lib/python3.11/site-packages/flask/app.py", line 867, in full_dispatch_request
    rv = self.dispatch_request()
         ^^^^^^^^^^^^^^^^^^^^^^^
  File "/home/varadv3/miniconda3/envs/microblog/lib/python3.11/site-packages/flask/app.py", line 852, in dispatch_request
    return self.ensure_sync(self.view_functions[rule.endpoint])(**view_args)
           ^^^^^^^^^^^^^^^^^^^^^^^^^^^^^^^^^^^^^^^^^^^^^^^^^^^^^^^^^^^^^^^^^
  File "/home/varadv3/miniconda3/envs/microblog/lib/python3.11/site-packages/flask_login/utils.py", line 290, in decorated_view
    return current_app.ensure_sync(func)(*args, **kwargs)
           ^^^^^^^^^^^^^^^^^^^^^^^^^^^^^^^^^^^^^^^^^^^^^^
  File "/home/varadv3/Documents/Master/v3_blogs/app/routes.py", line 16, in index
    print(4 / 0)
          ~~^~~
ZeroDivisionError: division by zero
